Workbook

Sheet Samleark
A1: Samleark for ejendomme
J4: Timer pr. uge
A5: DL | B5: Selskab | C5: Ejendoms nr | D5: Ejendom | E5: Adresse | F5: Post nr | G5: By | H5: Viceværter | I5: Kategori | J5: Vicevært | K5: Gartner | L5: SC | M5: Opstartsdato | N5: Slutdato | O5: Kommentar
A6: PNI | B6: 11 | C6: 187 | E6: Tornerosevej 127 | F6: 2730 | G6: Herlev | H6: Nicolai V. Jensen | I6: Erhverv | J6: ='1-Peter'!M10 -> 3.1538462 | K6: ='1-Peter'!N10 -> 1.9230769 | L6: ='1-Peter'!O10 -> 0.40384615 | M6: ='1-Peter'!$R$10 -> 42095
A7: PNI | B7: 11 | C7: 195 | D7: Tinghaven | E7: Telefonvej 2/Tinghøjvej 57, 59, 61, 63 og 65 | F7: 2860 | G7: Søborg | H7: Nicolai V. Jensen | I7: Boliger | J7: ='1-Peter'!M11 -> 11.711538 | K7: ='1-Peter'!N11 -> 5.1153846 | L7: ='1-Peter'!O11 -> 0 | M7: ='1-Peter'!$R$11 -> 42036
A8: PNI | B8: 11 | C8: 220 | E8: Ejby Industrivej 60-66 | F8: 2600 | G8: Glostrup | H8: Nicolai V. Jensen | I8: Erhverv | J8: ='1-Peter'!M12 -> 4.1153846 | K8: ='1-Peter'!N12 -> 2.3076923 | L8: ='1-Peter'!O12 -> 0
A9: PNI | B9: 11 | C9: 232 | E9: Mørkhøjvej 132 - 142 | F9: 2860 | G9: Søborg | H9: Nicolai V. Jensen | I9: Boliger | J9: ='1-Peter'!M13 -> 25.211538 | K9: ='1-Peter'!N13 -> 9.6153846 | L9: ='1-Peter'!O13 -> 4.8076923 | M9: ='1-Peter'!$R$13 -> 43070
A10: PNI | B10: 11 | C10: 493 | E10: Søborg Hovedgade 121-127/Andersen Nexøvej 3 | F10: 2860 | G10: Søborg | H10: Nicolai V. Jensen | I10: Boliger | J10: ='1-Peter'!M14 -> 7.0769231 | K10: ='1-Peter'!N14 -> 0.96153846 | L10: ='1-Peter'!O14 -> 0 | O10: ='1-Peter'!$U$14 -> Genforhandling - kan ikke finde opstartsdato
A11: PNI | B11: 11 | C11: 187 | E11: Tornerosevej 127 | F11: 2730 | G11: Herlev | H11: Allan Ringsborg | I11: Erhverv
A12: PNI | B12: 11 | C12: 195 | D12: Tinghaven | E12: Telefonvej 2/Tinghøjvej 57, 59, 61, 63 og 65 | F12: 2860 | G12: Søborg | H12: Allan Ringsborg | I12: Boliger
A13: PNI | B13: 11 | C13: 220 | E13: Ejby Industrivej 60-66 | F13: 2600 | G13: Glostrup | H13: Allan Ringsborg | I13: Erhverv
A14: PNI | B14: 11 | C14: 232 | E14: Mørkhøjvej 132 - 142 | F14: 2860 | G14: Søborg | H14: Allan Ringsborg | I14: Boliger
A15: PNI | B15: 11 | C15: 493 | E15: Søborg Hovedgade 121-127/Andersen Nexøvej 3 | F15: 2860 | G15: Søborg | H15: Allan Ringsborg | I15: Boliger
A16: PNI | B16: 11 | C16: 187 | E16: Tornerosevej 127 | F16: 2730 | G16: Herlev | H16: Kay Helt | I16: Erhverv
A17: PNI | B17: 11 | C17: 195 | D17: Tinghaven | E17: Telefonvej 2/Tinghøjvej 57, 59, 61, 63 og 65 | F17: 2860 | G17: Søborg | H17: Kay Helt | I17: Boliger
A18: PNI | B18: 11 | C18: 220 | E18: Ejby Industrivej 60-66 | F18: 2600 | G18: Glostrup | H18: Kay Helt | I18: Erhverv
A19: PNI | B19: 11 | C19: 232 | E19: Mørkhøjvej 132 - 142 | F19: 2860 | G19: Søborg | H19: Kay Helt | I19: Boliger
A20: PNI | B20: 11 | C20: 493 | E20: Søborg Hovedgade 121-127/Andersen Nexøvej 3 | F20: 2860 | G20: Søborg | H20: Kay Helt | I20: Boliger
A21: PNI | B21: 8 | C21: 217 | D21: G/F Søpark | E21: Mortonsvej 2 - 42 | F21: 2800 | G21: Kgs. Lyngby | H21: Kay Helt | I21: Boliger | J21: ='1-Peter'!M15 -> 0.51615385 | K21: ='1-Peter'!N15 -> 0 | L21: ='1-Peter'!O15 -> 0 | M21: ='1-Peter'!$R$15 -> 43922
A22: PNI | B22: 11 | C22: 306 | E22: Frederiksdalsvej 80 - 82/Frederiksdalsvej 80 A-E - 82 A-E | F22: 2830 | G22: Virum | H22: Kay Helt | I22: Boliger | J22: ='1-Peter'!M16 -> 1.0192308 | K22: ='1-Peter'!N16 -> 0 | L22: ='1-Peter'!O16 -> 0
A23: PNI | B23: 11 | C23: 499 | D23: Lyngby Søpark | E23: Mortonsvej 2 - 30 | F23: 2800 | G23: Kgs. Lyngby | H23: Kay Helt | I23: Boliger | J23: ='1-Peter'!M17 -> 15.634615 | K23: ='1-Peter'!N17 -> 0 | L23: ='1-Peter'!O17 -> 0
A24: PNI | B24: 11 | C24: 513 | E24: Øverødvej 3 A/Øverødvej 3 B | F24: 2840 | G24: Holte | H24: Kay Helt | I24: Boliger | J24: ='1-Peter'!M18 -> 4.75 | K24: ='1-Peter'!N18 -> 0.25 | L24: ='1-Peter'!O18 -> 0
A25: PNI | B25: 8 | C25: 217 | D25: G/F Søpark | E25: Mortonsvej 2 - 42 | F25: 2800 | G25: Kgs. Lyngby | H25: Nicolai V. Jensen | I25: Boliger
A26: PNI | B26: 11 | C26: 306 | E26: Frederiksdalsvej 80 - 82/Frederiksdalsvej 80 A-E - 82 A-E | F26: 2830 | G26: Virum | H26: Nicolai V. Jensen | I26: Boliger
A27: PNI | B27: 11 | C27: 499 | D27: Lyngby Søpark | E27: Mortonsvej 2 - 30 | F27: 2800 | G27: Kgs. Lyngby | H27: Nicolai V. Jensen | I27: Boliger
A28: PNI | B28: 11 | C28: 513 | E28: Øverødvej 3 A/Øverødvej 3 B | F28: 2840 | G28: Holte | H28: Nicolai V. Jensen | I28: Boliger
A29: PNI | B29: 8 | C29: 217 | D29: G/F Søpark | E29: Mortonsvej 2 - 42 | F29: 2800 | G29: Kgs. Lyngby | H29: Allan Ringsborg | I29: Boliger
A30: PNI | B30: 11 | C30: 306 | E30: Frederiksdalsvej 80 - 82/Frederiksdalsvej 80 A-E - 82 A-E | F30: 2830 | G30: Virum | H30: Allan Ringsborg | I30: Boliger
A31: PNI | B31: 11 | C31: 499 | D31: Lyngby Søpark | E31: Mortonsvej 2 - 30 | F31: 2800 | G31: Kgs. Lyngby | H31: Allan Ringsborg | I31: Boliger
A32: PNI | B32: 11 | C32: 513 | E32: Øverødvej 3 A/Øverødvej 3 B | F32: 2840 | G32: Holte | H32: Allan Ringsborg | I32: Boliger
A33: PNI | B33: 11 | C33: 135 | D33: Ketteholm | E33: Ketteholm 29 - 37, Ketteholm 53 - 55 Ketteholm 75 - 81 | F33: 2650 | G33: Hvidovre | H33: FS - SC | I33: Boliger | J33: ='1-Peter'!M19 -> 2.5769231 | K33: ='1-Peter'!N19 -> 0 | L33: ='1-Peter'!O19 -> 0 | M33: ='1-Peter'!$R$19 -> 43191
A34: PNI | B34: 11 | C34: 247 | D34: Jernholmen 6 - 10 | E34: Jernholmen 6 - 10 | F34: 2650 | G34: Hvidovre | H34: Henrik Kirchherr | I34: Erhverv | J34: ='1-Peter'!M20 -> 3.4423077 | K34: ='1-Peter'!N20 -> 2.8846154 | L34: ='1-Peter'!O20 -> 0.19230769 | M34: ='1-Peter'!$R$20 -> 42095
A35: PNI | B35: 11 | C35: 382 | E35: Taastrup Hovedgade 101 tidl. Køgevej | F35: 2630 | G35: Taastrup | H35: Henrik Kirchherr | I35: Erhverv | J35: ='1-Peter'!M21 -> 2.9615385 | K35: ='1-Peter'!N21 -> 0.57692308 | L35: ='1-Peter'!O21 -> 0 | M35: ='1-Peter'!$R$21 -> 42125
A36: PNI | B36: 11 | C36: 458 | D36: Amalieparken | E36: Amalieparken 7, 25, 41, Margrethevænget 3, 9, 15, Amalieparken 7, 25, 41 | F36: 2665 | G36: Vallensbæk Strand | H36: Henrik Kirchherr | I36: Boliger | J36: ='1-Peter'!M22 -> 14.038462 | K36: ='1-Peter'!N22 -> 0 | L36: ='1-Peter'!O22 -> 0 | M36: ='1-Peter'!$R$22 -> 42036
A37: PNI | B37: 11 | C37: 508 | E37: Hovedvejen 87 | F37: 2601 | G37: Glostrup | H37: Henrik Kirchherr | I37: Boliger | J37: ='1-Peter'!M23 -> 3.9230769 | K37: ='1-Peter'!N23 -> 0 | L37: ='1-Peter'!O23 -> 0
A38: PNI | B38: 11 | C38: 517 | E38: Hovedvejen 104-108 | F38: 2602 | G38: Glostrup | H38: Henrik Kirchherr | I38: Boliger | J38: ='1-Peter'!M24 -> 8.6538462 | K38: ='1-Peter'!N24 -> 0 | L38: ='1-Peter'!O24 -> 0
A39: PNI | B39: 11 | C39: 706 | E39: Hovedvejen 114-116/Heggelunds Allé 2/Højvangsvej 71 | F39: 2600 | G39: Glostrup | H39: Henrik Kirchherr | I39: Boliger | J39: ='1-Peter'!M25 -> 9.6153846 | K39: ='1-Peter'!N25 -> 0 | L39: ='1-Peter'!O25 -> 0
A40: PNI | B40: 11 | C40: 247 | D40: Jernholmen 6 - 10 | E40: Jernholmen 6 - 10 | F40: 2650 | G40: Hvidovre | H40: Henrik Schjoldager | I40: Erhverv
A41: PNI | B41: 11 | C41: 382 | E41: Taastrup Hovedgade 101 tidl. Køgevej | F41: 2630 | G41: Taastrup | H41: Henrik Schjoldager | I41: Erhverv
A42: PNI | B42: 11 | C42: 458 | D42: Amalieparken | E42: Amalieparken 7, 25, 41, Margrethevænget 3, 9, 15, Amalieparken 7, 25, 41 | F42: 2665 | G42: Vallensbæk Strand | H42: Henrik Schjoldager | I42: Boliger
...

Sheet Viceværter norm
B1: Fuldt navn | C1: Brugertype | D1: Normtid | E1: Lønnummer | F1: Medarb.nummer | G1: Mobilnr.
B2: 01 - Alexander Kirchherr | C2: Servicemedarbejder (FS) | D2: 37 | F2: 4870 | G2: 27901934
B3: 01 - Boye Jensen | C3: Servicemedarbejder (FS) | D3: 37 | F3: 4573 | G3: 27901875
B4: 01 - Christian Trajkovski | C4: Servicemedarbejder (FS) | D4: 30 | F4: 5820 | G4: 77890588
B5: 02 - Flemming Jespersen | C5: Servicemedarbejder (FS) | D5: 37 | F5: 4140 | G5: 27901879
B6: 02 - Henrik Ankerstjerne Hansen | C6: Servicemedarbejder (FS) | D6: 37 | F6: 4968 | G6: 27901941
B7: 02 - Kim Dullum | C7: Servicemedarbejder (FS) | D7: 37 | F7: 4719 | G7: 27901961
B8: 02 - Sten Faurschou | C8: Servicemedarbejder (FS) | D8: 37 | F8: 5202 | G8: 27901850
B9: 02 - Thor Hansen | C9: Servicemedarbejder (FS) | D9: 37 | F9: 4830 | G9: 27901917
B10: 03 - Hans Jørgen Thuesen | C10: Servicemedarbejder (FS) | D10: 30 | F10: 5208 | G10: 27901470
B11: 04 - Jakob Ståhl Mortensen | C11: Servicemedarbejder (FS) | D11: 37 | F11: 4960 | G11: 27901940
B12: 04 - Jørn Strenov | C12: Servicemedarbejder (FS) | D12: 37 | F12: 4598 | G12: 27901889
B13: 05 - Ejvind Andersen | C13: Servicemedarbejder (FS) | D13: 10 | F13: 5294 | G13: 27901974
... B37: 20 - Brian Frederiksen | C37: Servicemedarbejder (FS) | D37: 37 | F37: 5756 | G37: 27901985
B38: 21 - Jan Vaclav Hemmersam | C38: Servicemedarbejder (FS) | D38: 37 | F38: 5796
B39: André Sørensen | C39: Servicemedarbejder (FS) | D39: 37 | F39: 5665 | G39: 27901929
B40: Andreas Braagaard | C40: Vicevært (Fast) | D40: 37 | F40: 5114 | G40: 61556878
B41: Bjarne Pedersen | C41: Gartner | D41: 37 | F41: 5644 | G41: 27901871
B42: Bjørn David Schistad Handberg | C42: Gartner | D42: 37 | F42: 5834 | G42: 27901729
B43: Brian Borch Rasmussen | C43: Servicemedarbejder (FS) | D43: 37 | F43: 5761 | G43: 20109653
B44: Camilla Valim | C44: Gartner | D44: 37 | F44: 5683 | G44: 27901848
B45: Carsten Thorup Bjergegaard | C45: Servicemedarbejder (FS) | D45: 37 | F45: 4869 | G45: 27901935
B46: Clement Simon | C46: Servicemedarbejder (FS) | D46: 37 | F46: 4498 | G46: +4527901387
B47: Dan Jensen | C47: Vicevært (Fast) | D47: 37 | F47: 5005 | G47: 27901968
B48: Danny Nielsen | C48: Servicemedarbejder (FS) | D48: 37 | F48: 5189 | G48: 27901962
B49: David Price | C49: Servicemedarbejder (FS) | D49: 37 | F49: 5401 | G49: 27901877
B50: Emil Milo Lindblom | C50: Servicemedarbejder (FS) | D50: 37 | F50: 5771 | G50: 27901735
... B53: Finn Haumann | C53: Servicemedarbejder (FS) | D53: 37 | F53: 4768 | G53: 27901863
B54: Frank Farenzena | C54: Vicevært (Fast) | D54: 37 | F54: 5841
B55: Hans-Henrik Jakobsen | C55: Vicevært (Fast) | D55: 37 | F55: 5324
B56: Helmer Axel Schødts | C56: Servicemedarbejder (FS) | D56: 37 | F56: 4034
B57: Henning Søren Kjeldsen | C57: Servicemedarbejder (FS) | D57: 37 | F57: 4828 | G57: 27901855
B58: Henrik Büchner | C58: Gartner | D58: 37 | F58: 5832 | G58: 27901732
B59: Henrik Gram Schjoldager | C59: Servicemedarbejder (FS) | D59: 20 | F59: 4755 | G59: 77890573
B60: Henrik Kirchherr | C60: Servicemedarbejder (FS) | D60: 37 | F60: 4355 | G60: 77890572
B61: Henrik Tønnersen | C61: Servicemedarbejder (FS) | D61: 37 | F61: 5242 | G61: 27901954
B62: Henry Dalager Jeppesen | C62: Servicemedarbejder (FS) | D62: 37 | F62: 4653 | G62: 27901436
B63: Hubert Erichsen | C63: Vicevært (Fast) | D63: 37 | F63: 5508 | G63: 27901707
B64: Jan Agersten | C64: Servicemedarbejder (FS) | D64: 37 | F64: 5822 | G64: 27901628
B65: Jan Blindkilde | C65: Servicemedarbejder (FS) | D65: 37 | F65: 5237 | G65: +4561201356
...

Sheet 1-Peter
A1: Peter Nielsen - 12
A2: GRUPPE 1 - PKA
A3: Antal ejendomme | C3: =K7 -> 36 | J3: Erhverv | K3: =COUNTIFS(L:L,J3) -> 6
A4: Viceværter | J4: Boliger | K4: =COUNTIFS(L:L,J4) -> 29
J5: Grund | K5: =COUNTIFS(L:L,J5) -> 1
A6: Note: | J6: Andet | K6: =COUNTIFS(L:L,J6) -> 0
K7: =SUM(K3:K6) -> 36
M8: Timer pr. uge | P8: Kr/år
A9: DL | B9: Kunde | C9: Selskab | D9: Ejendoms nr | E9: Gruppe | F9: Ejendom | G9: Adresse | H9: Post nr | I9: By | J9: Viceværter | K9: Ny vicevært | L9: Kategori | M9: Vicevært | N9: Gartner | O9: Feje/suge | P9: CTS | Q9: SC | R9: Opstartsdato | S9: Slutdato | T9: FS-aftale | U9: Kommentar | V9: Antal: | W9: PT. DL
A10: PNI | B10: PKA | C10: 11 | D10: 187 | E10: 1 | G10: Tornerosevej 127 | H10: 2730 | I10: Herlev | J10: B. S. Ejendomsservice | L10: Erhverv | M10: =(50+100+4+10)/52 -> 3.1538462 | N10: =100/52 -> 1.9230769 | O10: =(18+3)/52 -> 0.40384615 | P10: 0 | Q10: =3400 -> 3400 | R10: 42095 | T10: JA | V10: 1 | W10: BFE
A11: PNI | B11: PKA | C11: 11 | D11: 195 | E11: 1 | F11: Tinghaven | G11: Telefonvej 2/Tinghøjvej 57, 59, 61, 63 og 65 | H11: 2860 | I11: Søborg | J11: Kay Helt & BS | L11: Boliger | M11: =(280+275+39+15)/52 -> 11.711538 | N11: =266/52 -> 5.1153846 | O11: =0 -> 0 | P11: 0 | Q11: 27880 | R11: 42036 | T11: JA | V11: 1
A12: PNI | B12: PKA | C12: 11 | D12: 220 | E12: 1 | G12: Ejby Industrivej 60-66 | H12: 2600 | I12: Glostrup | J12: B. S. Ejendomsservice | L12: Erhverv | M12: =(50+150+4+10)/52 -> 4.1153846 | N12: =120/52 -> 2.3076923 | O12: 0 | P12: 0 | Q12: =1020 -> 1020 | T12: JA | V12: 1 | W12: BFE
A13: PNI | B13: PKA | C13: 11 | D13: 232 | E13: 1 | G13: Mørkhøjvej 132 - 142 | H13: 2860 | I13: Søborg | J13: Kay Helt & BS | L13: Boliger | M13: =(500+735+49+27)/52 -> 25.211538 | N13: =(100+400)/52 -> 9.6153846 | O13: 4.8076923 | P13: 0 | Q13: =62220 -> 62220 | R13: 43070 | T13: JA | V13: 1
A14: PNI | B14: PKA | C14: 11 | D14: 493 | E14: 1 | G14: Søborg Hovedgade 121-127/Andersen Nexøvej 3 | H14: 2860 | I14: Søborg | J14: Kay Helt & BS | L14: Boliger | M14: =(160+140+53+15)/52 -> 7.0769231 | N14: =50/52 -> 0.96153846 | O14: 0 | P14: =21600 -> 21600 | Q14: =22100 -> 22100 | T14: JA | U14: Genforhandling - kan ikke finde opstartsdato | V14: 1
A15: PNI | B15: Ejerforening | C15: 8 | D15: 217 | E15: 1 | F15: G/F Søpark | G15: Mortonsvej 2 - 42 | H15: 2800 | I15: Kgs. Lyngby | J15: Kay Helt & BS | L15: Boliger | M15: =(12*0.5+52*0.17+12)/52 -> 0.51615385 | N15: 0 | O15: 0 | P15: 0 | Q15: =2537.5 -> 2537.5 | R15: 43922 | T15: JA | V15: 1
A16: PNI | B16: PKA | C16: 11 | D16: 306 | E16: 1 | G16: Frederiksdalsvej 80 - 82/Frederiksdalsvej 80 A-E - 82 A-E | H16: 2830 | I16: Virum | J16: B. S. Ejendomsservice | L16: Boliger | M16: =53/52 -> 1.0192308 | N16: 0 | O16: 0 | P16: 0 | Q16: =33660 -> 33660 | T16: JA | V16: 1 | W16: PAAN
A17: PNI | B17: PKA | C17: 11 | D17: 499 | E17: 1 | F17: Lyngby Søpark | G17: Mortonsvej 2 - 30 | H17: 2800 | I17: Kgs. Lyngby | J17: Thomas Rosenkvist | L17: Boliger | M17: =(625+48+140)/52 -> 15.634615 | N17: 0 | O17: 0 | P17: 0 | Q17: =44200 -> 44200 | T17: JA | V17: 1
A18: PNI | B18: PKA | C18: 11 | D18: 513 | E18: 1 | G18: Øverødvej 3 A/Øverødvej 3 B | H18: 2840 | I18: Holte | J18: Kay Helt | L18: Boliger | M18: =0.25+4+0.5 -> 4.75 | N18: 0.25 | O18: 0 | P18: 0 | Q18: =3060 -> 3060 | T18: JA | V18: 1 | W18: PAAN
A19: PNI | B19: PKA | C19: 11 | D19: 135 | E19: 1 | F19: Ketteholm | G19: Ketteholm 29 - 37, Ketteholm 53 - 55 Ketteholm 75 - 81 | H19: 2650 | I19: Hvidovre | J19: FS - SC | L19: Boliger | M19: =(130+4)/52 -> 2.5769231 | N19: 0 | O19: 0 | P19: 0 | Q19: =3740 -> 3740 | R19: 43191 | T19: JA | V19: 1 | W19: BFE
A20: PNI | B20: PKA | C20: 11 | D20: 247 | E20: 1 | F20: Jernholmen 6 - 10 | G20: Jernholmen 6 - 10 | H20: 2650 | I20: Hvidovre | J20: FS - Henrik Kirchherr | L20: Erhverv | M20: =(25+150+4)/52 -> 3.4423077 | N20: =150/52 -> 2.8846154 | O20: =10/52 -> 0.19230769 | P20: 0 | Q20: 2040 | R20: 42095 | T20: JA | V20: 1 | W20: BFE
A21: PNI | B21: PKA | C21: 11 | D21: 382 | E21: 1 | G21: Taastrup Hovedgade 101 tidl. Køgevej | H21: 2630 | I21: Taastrup | J21: FS - Henning Søren Kjeldsen | L21: Erhverv | M21: =(100+50+4)/52 -> 2.9615385 | N21: =30/52 -> 0.57692308 | O21: =0 -> 0 | P21: 0 | Q21: 1700 | R21: 42125 | T21: JA | V21: 1 | W21: BFE
A22: PNI | B22: PKA | C22: 11 | D22: 458 | E22: 1 | F22: Amalieparken | G22: Amalieparken 7, 25, 41, Margrethevænget 3, 9, 15, Amalieparken 7, 25, 41 | H22: 2665 | I22: Vallensbæk Strand | J22: FS - Henrik Kirchherr | L22: Boliger | M22: =(500+125+105)/52 -> 14.038462 | N22: 0 | O22: 0 | P22: =4745 -> 4745 | Q22: 48960 | R22: 42036 | T22: JA | V22: 1 | W22: BFE
A23: PNI | B23: PKA | C23: 11 | D23: 508 | E23: 1 | G23: Hovedvejen 87 | H23: 2600 | I23: Glostrup | J23: B. S. Ejendomsservice | L23: Boliger | M23: =(100+100+4)/52 -> 3.9230769 | N23: 0 | O23: 0 | P23: 0 | Q23: =2040 -> 2040 | T23: JA | V23: 1 | W23: BFE
A24: PNI | B24: PKA | C24: 11 | D24: 517 | E24: 1 | G24: Hovedvejen 104-108 | H24: 2600 | I24: Glostrup | J24: B. S. Ejendomsservice | L24: Boliger | M24: =(250+200)/52 -> 8.6538462 | N24: 0 | O24: 0 | P24: 0 | Q24: =10880 -> 10880 | T24: JA | V24: 1 | W24: BFE
A25: PNI | B25: PKA | C25: 11 | D25: 706 | E25: 1 | G25: Hovedvejen 114-116/Heggelunds Allé 2/Højvangsvej 71 | H25: 2600 | I25: Glostrup | J25: B. S. Ejendomsservice | L25: Boliger | M25: =(300+200)/52 -> 9.6153846 | N25: 0 | O25: 0 | P25: 0 | Q25: =5100 -> 5100 | T25: JA | V25: 1 | W25: BFE
A26: PNI | B26: PKA | C26: 11 | D26: 119 | E26: 1 | F26: Tømmergården | G26: Kastanievej 6-16/Smedelundsgade 34-38 | H26: 4300 | I26: Holbæk | J26: Jan Bruun | L26: Boliger | M26: =(550+325)/52 -> 16.826923 | N26: 2.8846154 | O26: 0 | P26: 0 | Q26: 29240 | T26: JA | V26: 1
A27: PNI | B27: PKA | C27: 11 | D27: 143 | E27: 1 | F27: Egegården | G27: Gyvelvej 14 A-D | H27: 4000 | I27: Roskilde | J27: Michael Toft Nielsen/John Kelly | L27: Boliger | M27: =(60+300+11)/52 -> 7.1346154 | N27: =225/52 -> 4.3269231 | O27: 0 | P27: 0 | Q27: =10880 -> 10880 | T27: JA | V27: 1
A28: PNI | B28: PKA | C28: 11 | D28: 144 | E28: 1 | F28: Bakkedraget | G28: Bakkedraget 14 - 22/Toftegårdsvej 10 - 23 | H28: 4500 | I28: Nykøbing Sj | J28: Jan Bruun | L28: Boliger | M28: =(75+150)/52 -> 4.3269231 | N28: =150/52 -> 2.8846154 | O28: 0 | P28: 0 | Q28: =5100 -> 5100 | T28: JA | V28: 1
A29: PNI | B29: PKA | C29: 11 | D29: 224 | E29: 1 | G29: Jernbanegade 2A - 6D/Casinotorvet 2 - 6 | H29: 4200 | I29: Slagelse | J29: Henning Toft Larsen/Jytte Petersen | L29: Boliger | M29: =(700+800+88)/52 -> 30.538462 | N29: 3.1730769 | O29: 0 | P29: 0 | Q29: =42840 -> 42840 | T29: JA | V29: 1
A30: PNI | B30: PKA | C30: 11 | D30: 233 | E30: 1 | F30: Møllehusparken | G30: Vestergade 12 - 22/Møllehusvej 121 - 125 | H30: 4000 | I30: Roskilde | J30: Michael Toft Nielsen/John Kelly | L30: Boliger | M30: =(240+600+77)/52 -> 17.634615 | N30: =210/52 -> 4.0384615 | O30: 0 | P30: 0 | Q30: =48960 -> 48960 | T30: JA | V30: 1
A31: PNI | B31: PKA | C31: 11 | D31: 345 | E31: 1 | G31: Kildemarksvej 125 - 131 | H31: 4700 | I31: Næstved | J31: Sabrina Ripley | L31: Boliger | M31: =(200+200+25)/52 -> 8.1730769 | N31: =100/52 -> 1.9230769 | O31: 0 | P31: 0 | Q31: =11900 -> 11900 | T31: JA | V31: 1
A32: PNI | B32: PKA | C32: 11 | D32: 368 | E32: 1 | G32: Kildemarksvej 115 - 123 | H32: 4700 | I32: Næstved | J32: Sabrina Ripley | L32: Boliger | M32: =(200+200+35)/52 -> 8.3653846 | N32: =100/52 -> 1.9230769 | O32: 0 | P32: 0 | Q32: =14280 -> 14280 | T32: JA | V32: 1
A33: PNI | B33: PKA | C33: 11 | D33: 380 | E33: 1 | G33: Algade 33 | H33: 4000 | I33: Roskilde | J33: Michael Toft Nielsen/John Kelly | L33: Boliger | M33: =(15+300+4)/52 -> 6.1346154 | N33: =8/52 -> 0.15384615 | O33: 0 | P33: 0 | Q33: 3060 | T33: JA | V33: 1
A34: PNI | B34: PKA | C34: 11 | D34: 408 | E34: 1 | F34: Klosterhaven | G34: Klosterhaven 1-47/Ingemannsvej 8-24 | H34: 4180 | I34: Sorø | J34: Sabrina Ripley | L34: Boliger | M34: =(250+500+25)/52 -> 14.903846 | N34: =650/52 -> 12.5 | O34: 0 | P34: 0 | Q34: 26860 | T34: JA | V34: 1
A35: PNI | B35: PKA | C35: 11 | D35: 416 | E35: 1 | G35: Hersegade 28 | H35: 4000 | I35: Roskilde | J35: Michael Toft Nielsen/John Kelly | L35: Boliger | M35: =(6+200+4)/52 -> 4.0384615 | N35: =2/52 -> 0.038461538 | O35: 0 | P35: 0 | Q35: =1020 -> 1020 | T35: JA | V35: 1
A36: PNI | B36: PKA | C36: 11 | D36: 423 | E36: 1 | G36: Hærvigsgade 9-13/Vestre Havnevej 22-24 | H36: 4400 | I36: Kalundborg | J36: Jan Bruun | L36: Boliger | M36: =(150+150+28)/52 -> 6.3076923 | N36: =90/52 -> 1.7307692 | O36: 0 | P36: 0 | Q36: =10200 -> 10200 | R36: 42887 | T36: JA | V36: 1
A37: PNI | B37: PKA | C37: 11 | D37: 429 | E37: 1 | F37: Emmasgården | G37: Kongebakken 54 - 60 | H37: 4000 | I37: Roskilde | J37: Michael Toft Nielsen/John Kelly | L37: Boliger | M37: =(70+300+32)/52 -> 7.7307692 | N37: =225/52 -> 4.3269231 | O37: 0 | P37: 0 | Q37: =14620 -> 14620 | T37: JA | V37: 1
A38: PNI | B38: PKA | C38: 11 | D38: 504 | E38: 1 | G38: Lindevej 1/Hovedgaden 24 | H38: 4140 | I38: Borup | J38: Birgith Lystrup Thomsen | L38: Boliger | M38: =(100+100+7)/52 -> 3.9807692 | N38: =30/52 -> 0.57692308 | O38: 0 | P38: 0 | Q38: =2720 -> 2720 | T38: JA | V38: 1
A39: PNI | B39: Ejerforening | C39: 8 | D39: 538 | E39: 1 | F39: E/F Bagsværddal | G39: Bagsværddal 20/Bagsværd Hovedgade 115 | H39: 2880 | I39: Bagsværd | J39: ? | L39: Boliger | T39: NEJ | U39: Tilsyneladende ingen FS-aftale | V39: 1
A40: PNI | B40: PKA | C40: 11 | D40: 262 | E40: 1 | F40: Nygade | G40: Nygade 20-30 | H40: 4800 | I40: Nykøbing F | J40: Jan Petersen | L40: Boliger | T40: JA | U40: Ingen FS - MIC undersøger sagen | V40: 1
...

Sheet 1-Lars-Peter
A1: Lars-Peter Norsker - 17
A2: GRUPPE 1 - PKA
A3: Antal ejendomme | C3: =K7 -> 24 | J3: Erhverv | K3: =COUNTIFS(L:L,J3) -> 2
A4: Viceværter: | J4: Boliger | K4: =COUNTIFS(L:L,J4) -> 19
J5: Grund | K5: =COUNTIFS(L:L,J5) -> 1
A6: Note: | J6: Andet | K6: =COUNTIFS(L:L,J6) -> 2
K7: =SUM(K3:K6) -> 24
M8: Timer pr. uge | P8: Kr/år
A9: DL | B9: Kunde | C9: Selskab | D9: Ejendoms nr | E9: Gruppe | F9: Ejendom | G9: Adresse | H9: Post nr | I9: By | J9: Viceværter | K9: Ny vicevært | L9: Kategori | M9: Vicevært | N9: Gartner | O9: Feje/suge | P9: CTS | Q9: SC | R9: Opstartsdato | S9: Slutdato | T9: FS-aftale | U9: Kommentar | V9: Antal: | W9: PT. DL
A10: LPN | B10: PKA | C10: 11 | D10: 447 | E10: 1 | G10: Toftegårds Allé 40-42/Lyshøj Allé 2 - 6 | H10: 2500 | I10: Valby | J10: FS - Finn Transtrøm/Jacob Ståhl/Allan Schumann | K10: FS - Finn Transtrøm - Henrik Jensen | L10: Boliger | M10: =(380+100+11)/52 -> 9.4423077 | N10: =100/52 -> 1.9230769 | O10: 0 | P10: 0 | Q10: =16320 -> 16320 | T10: JA | V10: 1
A11: LPN | B11: PKA | C11: 11 | D11: 467 | E11: 1 | G11: Carl Jacobsens Vej 17/VALBY 1312 | H11: 2500 | I11: Valby | J11: FS - Finn Transtrøm/Jacob Ståhl/Allan Schumann | K11: FS - Finn Transtrøm - Henrik Jensen | L11: Boliger | M11: =(530+465+84)/52 -> 20.75 | N11: =280/52 -> 5.3846154 | O11: 0 | P11: 0 | Q11: =42500 -> 42500 | T11: JA | V11: 1
A12: LPN | B12: PKA | C12: 11 | D12: 491 | E12: 1 | F12: Ballinghus | G12: Ib Schønbergs Allé 11-17/Poul Reichhardts Vej 10-16 | H12: 2500 | I12: Valby | J12: FS - Finn Transtrøm/Jacob Ståhl/Allan Schumann | K12: FS - Finn Transtrøm - Henrik Jensen | L12: Boliger | M12: =(150+300+70)/52 -> 10 | N12: 1.7307692 | O12: =32.5/52 -> 0.625 | P12: 0 | Q12: =19040 -> 19040 | R12: 42036 | T12: JA | V12: 1
A13: LPN | B13: PKA | C13: 11 | D13: 970 | E13: 1 | G13: Poppelstykket 12-50, Følager 16 | H13: 2450 | I13: København SV | J13: FS - Finn Transtrøm/Jacob Ståhl/Allan Schumann | K13: FS - Finn Transtrøm - Henrik Jensen | L13: Boliger | M13: =(530+600+88)/52 -> 23.423077 | N13: =185/52 -> 3.5576923 | O13: 0 | P13: 0 | Q13: =44880 -> 44880 | R13: 43115 | T13: JA | V13: 1
A14: LPN | B14: PKA | C14: 11 | D14: 330 | E14: 1 | F14: Hortensia hus | G14: Grønttorvet/Unavngiven Vej 14 Vb 1/ Paradisæblevej 50-74 | H14: 2500 | I14: Valby | J14: HP Ejendomsservice | L14: Boliger | T14: NEJ | U14: Ingen FS | V14: 1
A15: LPN | B15: PKA | C15: 11 | D15: 331 | E15: 1 | F15: Lathyrus Hus | G15: Grønttorvet/Paradisæblevej 84-108/ | H15: 2500 | I15: Valby | J15: HP Ejendomsservice | L15: Boliger | T15: NEJ | U15: Ingen FS | V15: 1
A16: LPN | B16: PKA | C16: 11 | D16: 332 | E16: 1 | F16: Kamelia Hus | G16: Elstarvej 20-22 | H16: 2500 | I16: Valby | J16: HP Ejendomsservice | L16: Boliger | T16: NEJ | U16: Ingen FS | V16: 1
A17: LPN | B17: PKA | C17: 11 | D17: 333 | E17: 1 | F17: Rhododendron Hus | G17: Rubinolavej 4-10, James Grievevej 1-7, Paradisæblevej 40-46, Retortvej 37-39 | H17: 2500 | I17: Valby | J17: HP Ejendomsservice | L17: Boliger | T17: NEJ | U17: Ingen FS | V17: 1
A18: LPN | B18: PKA | C18: 11 | D18: 335 | E18: 1 | F18: Ranunkel Hus | H18: 2500 | I18: Valby | J18: HP Ejendomsservice | L18: Boliger | T18: NEJ | U18: Ingen FS | V18: 1
A19: LPN | B19: PKA | C19: 11 | D19: 338 | E19: 1 | F19: Grønttorvet | G19: Byggefelt 15 | H19: 2500 | I19: Valby | L19: Andet | T19: NEJ | U19: Ingen FS | V19: 1
A20: LPN | B20: PKA | C20: 11 | D20: 153 | E20: 1 | F20: Grunden - Dalgas Have | G20: Dalgas Have 1 - 76 | H20: 2000 | I20: Frederiksberg | J20: - | L20: Grund | T20: NEJ | U20: Ingen FS | V20: 1
A21: LPN | B21: PKA | C21: 11 | D21: 343 | E21: 1 | G21: La Cours Vej 4 | H21: 2000 | I21: Frederiksberg | J21: FS - Leif Nielsen/Emil/Juan | L21: Boliger | M21: =(20+20+4)/52 -> 0.84615385 | N21: =10/52 -> 0.19230769 | O21: 0 | P21: 0 | Q21: =2125 -> 2125 | T21: JA | V21: 1
A22: LPN | B22: PKA | C22: 11 | D22: 444 | E22: 1 | G22: Godthåbsvej 70 - 72/Nordre Fasanvej 83 | H22: 2000 | I22: Frederiksberg | J22: FS - Leif Nielsen/Emil/Juan | L22: Boliger | M22: =(77+375+25)/52 -> 9.1730769 | N22: 0 | O22: 0 | P22: 0 | Q22: =8500 -> 8500 | T22: JA | V22: 1
A23: LPN | B23: PKA | C23: 11 | D23: 494 | E23: 1 | F23: Dalgas Have | G23: Dalgas Have 1 - 3/Dalgas Have 27 - 29/Dalgas Have 2 - 76 | H23: 2000 | I23: Frederiksberg | J23: FS - Leif Nielsen/Emil/Juan | L23: Boliger | M23: =(2577+1866+95+400)/52 -> 94.961538 | N23: =1178/52 -> 22.653846 | O23: =600/52 -> 11.538462 | P23: 0 | Q23: =103275 -> 103275 | T23: JA | V23: 1
A24: LPN | B24: PKA | C24: 11 | D24: 502 | E24: 1 | G24: Gammel Kongevej 98 | H24: 1850 | I24: Frederiksberg C | J24: FS - Leif Nielsen/Emil/Juan | L24: Boliger | M24: =(75+125+4)/52 -> 3.9230769 | N24: 0 | O24: 0 | P24: 0 | Q24: =2550 -> 2550 | T24: JA | V24: 1
A25: LPN | B25: PKA | C25: 11 | D25: 519 | E25: 1 | G25: Falkoner Allé 53 - 55 | H25: 2000 | I25: Frederiksberg | J25: FS - Leif Nielsen/Emil/Juan | L25: Boliger | M25: =(75+200+28)/52 -> 5.8269231 | N25: 0 | O25: 0 | P25: 0 | Q25: =16575 -> 16575 | T25: JA | V25: 1
A26: LPN | B26: PKA | C26: 11 | D26: 784 | E26: 1 | G26: Gammel Kongevej 178/Falkoner Allé 2-4 | H26: 1850 | I26: Frederiksberg C | J26: FS - Leif Nielsen/Emil/Juan | L26: Boliger | M26: =(55+160+18)/52 -> 4.4807692 | N26: =15/52 -> 0.28846154 | O26: 0 | P26: 0 | Q26: =5100 -> 5100 | T26: JA | V26: 1
A27: LPN | B27: PKA | C27: 11 | D27: 152 | E27: 1 | G27: Løngangsstræde 23 | H27: 1468 | I27: København K | J27: FS - Maj-Britt Larsen | L27: Boliger | M27: =(100+215+4)/52 -> 6.1346154 | N27: 1.3846154 | O27: 0 | P27: 0 | Q27: =3520 -> 3520 | T27: JA | V27: 1
A28: LPN | B28: PKA | C28: 11 | D28: 328 | E28: 1 | G28: Klerkegade 31 | H28: 1308 | I28: København K | J28: FS - Maj-Britt Larsen | L28: Boliger | M28: =(20+50+4)/52 -> 1.4230769 | N28: =14/52 -> 0.26923077 | O28: 0 | P28: 0 | Q28: =1920 -> 1920 | T28: JA | V28: 1
A29: LPN | B29: PKA | C29: 11 | D29: 401 | E29: 1 | F29: Dronningegården | G29: Dronningens Tværgade 23 - 35/Borgergade 15 | H29: 1302 | I29: København K | J29: FS - Maj-Britt Larsen | L29: Boliger | M29: =(200+550+70+335)/52 -> 22.211538 | N29: 0 | O29: 0 | P29: 0 | Q29: =50240 -> 50240 | T29: JA | V29: 1
A30: LPN | B30: PKA | C30: 11 | D30: 506 | E30: 1 | G30: Kongens Nytorv 24/Store Kongensgade 6 | H30: 1050 | I30: København K | J30: FS - Maj-Britt Larsen | L30: Boliger | M30: =(35+155+7)/52 -> 3.7884615 | N30: 0 | O30: 0 | P30: 0 | Q30: =4480 -> 4480 | T30: JA | V30: 1
A31: LPN | C31: 9 | D31: 469 | E31: 1 | F31: P-lauget Artillerihaven | H31: 2300 | I31: København S | L31: Erhverv | M31: =183/52 -> 3.5192308 | N31: 0 | O31: =16/52 -> 0.30769231 | P31: 0 | Q31: =595 -> 595 | R31: 42036 | T31: JA | V31: 1
A32: LPN | B32: PKA | C32: 11 | D32: 215 | E32: 1 | G32: Nørre Voldgade 90 - 92/Rosenborggade 1, 1130 Kbh. K/Frederiksborggade 8, 1360 Kbh. K | H32: 1358 | I32: København K | J32: Per Johan Christensen | L32: Erhverv | T32: NEJ | U32: Ingen FS | V32: 1
A33: LPN | B33: PKA | C33: 11 | D33: 496 | E33: 1 | F33: PKA - spec byggeudg. | G33: Dalgas Have | H33: 2000 | I33: Frederiksberg | J33: - | L33: Andet | T33: NEJ | U33: Ingen FS | V33: 1

Sheet 1-Patrick
A1: Patrick - 11
A2: GRUPPE 1 - PKA
A3: Antal ejendomme | C3: =K7 -> 34 | J3: Erhverv | K3: =COUNTIFS(L:L,J3) -> 4
A4: Viceværter | J4: Boliger | K4: =COUNTIFS(L:L,J4) -> 30
J5: Grund | K5: =COUNTIFS(L:L,J5) -> 0
A6: Note: | J6: Andet | K6: =COUNTIFS(L:L,J6) -> 0
K7: =SUM(K3:K6) -> 34
M8: Timer pr. uge | P8: Kr/år
A9: DL | B9: Kunde | C9: Selskab | D9: Ejendoms nr | E9: Gruppe | F9: Ejendom | G9: Adresse | H9: Post nr | I9: By | J9: Viceværter | K9: Ny vicevært | L9: Kategori | M9: Vicevært | N9: Gartner | O9: Feje/suge | P9: CTS | Q9: SC | R9: Opstartsdato | S9: Slutdato | T9: FS-aftale | U9: Kommentar | V9: Antal: | W9: PT. DL
A10: PAAN | B10: Ejerforening | C10: 8 | D10: 960 | E10: 1 | F10: Den Overordnede G/F Margretheholm | G10: Margretheholmvej 4 m.fl. | H10: 1432 | I10: København K | J10: FS - Jørn Strenov/Michael Rasmussen | L10: Boliger | M10: =0.1+14.5+0.6 -> 15.2 | N10: =14.3 -> 14.3 | O10: =(4*8)/52 -> 0.61538462 | P10: 0 | Q10: =9800 -> 9800 | R10: 43466 | T10: JA | V10: 1 | W10: BFE
A11: PAAN | B11: Ejerforening | C11: 8 | D11: 965 | E11: 1 | F11: E/F Udsigten Margretheholm | G11: Margretheholmsvej 4 m.fl. | H11: 1432 | I11: København K | J11: FS - Jørn Strenov/Michael Rasmussen | L11: Boliger | M11: =577/52 -> 11.096154 | N11: =179.5/52 -> 3.4519231 | O11: 0 | P11: 0 | Q11: =61830 -> 61830 | R11: 42156 | T11: JA | V11: 1 | W11: BFE
A12: PAAN | B12: Ejerforening | C12: 8 | D12: 967 | E12: 1 | F12: Parkeringslauget Udsigten Margretheholm | G12: Margretheholmsvej 4 m.fl. | H12: 1432 | I12: København K | J12: FS - Jørn Strenov/Michael Rasmussen | L12: Boliger | M12: =149.5/52 -> 2.875 | N12: 0 | O12: =12/52 -> 0.23076923 | P12: 0 | Q12: =20485 -> 20485 | R12: 42217 | T12: JA | V12: 1 | W12: BFE
A13: PAAN | B13: PKA | C13: 11 | D13: 309 | E13: 1 | F13: Konstabelbygningen | G13: Luftmarinegade 1-3 | H13: 1432 | I13: København K | J13: FS - Jørn Strenov/Michael Rasmussen | L13: Boliger | M13: =(450+308+10)/52 -> 14.769231 | N13: =69.5/52 -> 1.3365385 | O13: =26/52 -> 0.5 | P13: =33306.25 -> 33306.25 | Q13: =29400 -> 29400 | R13: 42050 | T13: JA | U13: Scannet FS-aftale siger denne dato - kalkulationer viser en anden, 01/03/2016 | V13: 1 | W13: BFE
A14: PAAN | B14: PKA | C14: 11 | D14: 465 | E14: 1 | F14: Margretheholmen | G14: Margretheholmsvej 4-54 (Nr. 4-54 lejeboliger - Blok 3-6 - 328 lejemål Nr. 56-76 Ejerlej. - Blok 1 - 2) | H14: 1432 | I14: København K | J14: FS - Jørn Strenov/Michael Rasmussen | L14: Boliger | M14: =312/52 -> 6 | N14: 0 | O14: 0 | P14: 0 | Q14: =127400 -> 127400 | R14: 42217 | T14: JA | V14: 1 | W14: BFE
A15: PAAN | B15: PKA | C15: 11 | D15: 105 | E15: 1 | F15: Soldalen | G15: Kastrupvej 113-117/Syriensvej 8-12/Persiensvej 2/Kastrupvej 113-117 | H15: 2300 | I15: København S | J15: Jakob Ståhl Mortensen -Michael Nedergaard | L15: Boliger | M15: =2.9+5.4 -> 8.3 | N15: 2.6 | O15: 0 | P15: 0 | Q15: =35700 -> 35700 | R15: 43084 | T15: JA | V15: 1 | W15: BFE
A16: PAAN | B16: PKA | C16: 11 | D16: 446 | E16: 1 | F16: Amagerbrogade 193-195 | G16: Amagerbrogade 193-195/Smyrnavej 2-4 | H16: 2300 | I16: København S | J16: Michael Nedergaard | L16: Boliger | M16: =1.2+2.5 -> 3.7 | N16: 0.3 | O16: 0 | P16: 0 | Q16: =18900 -> 18900 | R16: 43084 | T16: JA | V16: 1 | W16: BFE
A17: PAAN | B17: PKA | C17: 11 | D17: 728 | E17: 1 | G17: Hallandsgade 2-8/Amagerbrogade 38 | H17: 2300 | I17: København S | J17: Michael Nedergaard | L17: Boliger | M17: =(27+137+4+52)/52 -> 4.2307692 | N17: 0 | O17: 0 | P17: 0 | Q17: =3060 -> 3060 | T17: JA | V17: 1 | W17: BFE
A18: PAAN | B18: E/F | C18: 800 | D18: 100 | E18: 1 | F18: E/F Quintus Bastion | G18: Krudtløbsvej 10-36 | H18: 1436 | I18: København K | J18: Michael Rasmussen | L18: Boliger | M18: =0.7+3.4+0.3 -> 4.4 | N18: 3.9 | O18: 0 | P18: 0 | Q18: =9324 -> 9324 | R18: 43862 | T18: JA | V18: 1
A19: PAAN | B19: PKA | C19: 11 | D19: 492 | E19: 1 | F19: Stationsvej 4-8 | G19: Stationsvej 4-8/Frederiksborgvej 28 | H19: 3650 | I19: Ølstykke | J19: Ole Jensen | L19: Boliger | M19: =(72+70+14)/52 -> 3 | N19: =70/52 -> 1.3461538 | O19: 0 | P19: 0 | Q19: =8160 -> 8160 | R19: 42036 | T19: JA | V19: 1
A20: PAAN | B20: PKA | C20: 11 | D20: 134 | E20: 1 | F20: Rådyrvænget | G20: Rådyrvænget 1, 10-14, 24-28 & 36-40 | H20: 3450 | I20: Allerød | J20: FS - kun flyttesyn+grønt | L20: Boliger | M20: =(30+4)/52 -> 0.65384615 | N20: =70/52 -> 1.3461538 | O20: 0 | P20: 0 | Q20: =3400 -> 3400 | R20: 42979 | T20: JA | V20: 1
A21: PAAN | B21: PKA | C21: 11 | D21: 231 | E21: 1 | F21: Farumhus | G21: Farum Hovedgade 2A-B | H21: 3520 | I21: Farum | J21: Ole Jensen | L21: Erhverv | M21: =(100+200+11)/52 -> 5.9807692 | N21: =200/52 -> 3.8461538 | O21: 0 | P21: 0 | Q21: =18360 -> 18360 | T21: JA | V21: 1
A22: PAAN | B22: PKA | C22: 11 | D22: 271 | E22: 1 | G22: Frederikshave 2 | H22: 3400 | I22: Hillerød | J22: Nita Senning-Larsen | L22: Boliger | M22: =(36+100+11)/52 -> 2.8269231 | N22: =100/52 -> 1.9230769 | O22: =4/52 -> 0.076923077 | P22: 0 | Q22: =6120 -> 6120 | R22: 42979 | T22: JA | V22: 1
A23: PAAN | B23: PKA | C23: 11 | D23: 286 | E23: 1 | G23: Frederikshave 6 - 36 | H23: 3400 | I23: Hillerød | J23: Nita Senning-Larsen | L23: Boliger | M23: =(300+500+42)/52 -> 16.192308 | N23: =500/52 -> 9.6153846 | O23: =6/52 -> 0.11538462 | P23: 0 | Q23: =32640 -> 32640 | R23: 42979 | T23: JA | V23: 1
A24: PAAN | B24: PKA | C24: 11 | D24: 313 | E24: 1 | F24: Hildis Have | G24: Søndre Jernbanevej 25 | H24: 3400 | I24: Hillerød | J24: Nita Senning-Larsen | L24: Boliger | M24: =(300+600+4)/52 -> 17.384615 | N24: =200/52 -> 3.8461538 | O24: 0 | P24: 0 | Q24: 2380 | R24: 43617 | T24: JA | V24: 1
A25: PAAN | B25: PKA | C25: 11 | D25: 319 | E25: 1 | F25: The Hill | G25: Søndre Jernbanevej 31-(vilaen)/Vibekevej 1- 3A - 3E, 5A-5B | H25: 3400 | I25: Hillerød | J25: Carsten Ingolf Christiansen | L25: Boliger | M25: =(300+400+25)/52 -> 13.942308 | N25: =200/52 -> 3.8461538 | O25: 0 | P25: 0 | Q25: =24140 -> 24140 | R25: 43087 | T25: JA | V25: 1
A26: PAAN | B26: PKA | C26: 11 | D26: 364 | E26: 1 | G26: Milnersvej 13 A + B | H26: 3400 | I26: Hillerød | J26: Nita Senning-Larsen | L26: Boliger | M26: =(25+25+4)/52 -> 1.0384615 | N26: 0 | O26: 0 | P26: 0 | Q26: 1020 | R26: 42979 | T26: JA | V26: 1
A27: PAAN | B27: PKA | C27: 11 | D27: 392 | E27: 1 | G27: Farum Hovedgade 14 | H27: 3520 | I27: Farum | J27: Ole Jensen | L27: Erhverv | M27: =(80+4)/52 -> 1.6153846 | N27: 0 | O27: 0 | P27: 0 | Q27: 340 | T27: JA | V27: 1
A28: PAAN | B28: PKA | C28: 11 | D28: 396 | E28: 1 | G28: Jernbanegade 13 - 13 A | H28: 3600 | I28: Frederikssund | J28: Ole Jensen | L28: Boliger | M28: =(40+150+18)/52 -> 4 | N28: 0 | O28: 0 | P28: 0 | Q28: =5780 -> 5780 | T28: JA | V28: 1
A29: PAAN | B29: PKA | C29: 11 | D29: 409 | E29: 1 | F29: Ved Skansebakken | G29: Ved Skansebakken | H29: 3400 | I29: Hillerød | J29: Nita Senning-Larsen | L29: Boliger | M29: =(25+4)/52 -> 0.55769231 | N29: 0 | O29: 0 | P29: 0 | Q29: 4420 | R29: 42979 | T29: JA | V29: 1
A30: PAAN | B30: PKA | C30: 11 | D30: 414 | E30: 2 | G30: Rådyrvænget 3 | H30: 3450 | I30: Allerød | J30: Ole Jensen | L30: Boliger | M30: =(30+4)/52 -> 0.65384615 | N30: =70/52 -> 1.3461538 | O30: 0 | P30: 0 | Q30: =3400 -> 3400 | R30: 42979 | T30: JA | V30: 1
A31: PAAN | B31: PKA | C31: 11 | D31: 454 | E31: 1 | G31: Jernbanegade 31 | H31: 3600 | I31: Frederikssund | J31: Ole Jensen | L31: Boliger | M31: =(4+70+4)/52 -> 1.5 | N31: 0 | O31: 0 | P31: 0 | Q31: 1700 | T31: JA | V31: 1
A32: PAAN | B32: PKA | C32: 11 | D32: 357 | E32: 1 | F32: Hildis Have | G32: Vibekevej 7, Søndre Jernbanevej 25 | H32: 3400 | I32: Hillerød | L32: Boliger | T32: NEJ | U32: Tilsyneladende ingen FS-aftale | V32: 1
A33: PAAN | B33: PKA | C33: 11 | D33: 304 | E33: 1 | G33: Strandvejen 3A - 11E | H33: 3390 | I33: Hundested | J33: Carsten Baltzar | L33: Boliger | T33: NEJ | U33: Ingen FS-aftale - MIC undersøger | V33: 1 | W33: PNI
A34: PAAN | B34: PKA | C34: 11 | D34: 189 | E34: 1 | G34: Lille Ellekongsstræde 1-9/Sct. Mortensgade 12-18 | H34: 3700 | I34: Rønne | J34: Michael Falck | L34: Boliger | T34: NEJ | U34: Tilsyneladende ingen FS-aftale | V34: 1 | W34: PNI
A35: PAAN | B35: PKA | C35: 11 | D35: 425 | E35: 1 | G35: Østergade 42 - 44 | H35: 3700 | I35: Rønne | J35: Michael Falck | L35: Boliger | T35: NEJ | U35: Tilsyneladende ingen FS-aftale | V35: 1
A36: PAAN | B36: PKA | C36: 11 | D36: 154 | E36: 1 | G36: Sophie Brahes Gade 50 | H36: 3000 | I36: Helsingør | J36: Harley Christiansen | L36: Erhverv | M36: =(100+150+4)/52 -> 4.8846154 | N36: =25/52 -> 0.48076923 | O36: 0 | P36: 0 | Q36: =2380 -> 2380 | T36: JA | V36: 1
A37: PAAN | B37: PKA | C37: 11 | D37: 191 | E37: 1 | G37: Sophie Magdelenes Vej 2 B-G | H37: 3460 | I37: Birkerød | J37: Eddie Sarelius | L37: Boliger | M37: =(100+50+21+100)/52 -> 5.2115385 | N37: =100/52 -> 1.9230769 | O37: 0 | P37: 0 | Q37: =7480 -> 7480 | T37: JA | V37: 1
A38: PAAN | B38: PKA | C38: 11 | D38: 193 | E38: 1 | G38: Sophie Magdelenes Vej 3 A-F | H38: 3460 | I38: Birkerød | J38: Eddie Sarelius | L38: Boliger | M38: =(50+100+25+100)/52 -> 5.2884615 | N38: =100/52 -> 1.9230769 | O38: 0 | P38: 0 | Q38: =9180 -> 9180 | T38: JA | V38: 1
A39: PAAN | B39: PKA | C39: 11 | D39: 198 | E39: 1 | G39: Biskop Svanes Vej 71 B - H | H39: 3460 | I39: Birkerød | J39: Eddie Sarelius | L39: Boliger | M39: =(50+100+11)/52 -> 3.0961538 | N39: =110/52 -> 2.1153846 | O39: 0 | P39: 0 | Q39: =3060 -> 3060 | T39: JA | V39: 1
A40: PAAN | B40: PKA | C40: 11 | D40: 199 | E40: 1 | G40: Biskop Svanes Vej 61 A-B | H40: 3460 | I40: Birkerød | J40: Eddie Sarelius | L40: Boliger | M40: =(50+100+18)/52 -> 3.2307692 | N40: =110/52 -> 2.1153846 | O40: 0 | P40: 0 | Q40: =4080 -> 4080 | T40: JA | V40: 1
...

Sheet 1-René
A1: René da Silva Mejborn - 16
A2: GRUPPE 1 - PKA
A3: Antal ejendomme | C3: =K7 -> 28 | J3: Erhverv | K3: =COUNTIFS(L:L,J3) -> 3
A4: Viceværter: | J4: Boliger | K4: =COUNTIFS(L:L,J4) -> 25
A5: NYT OMRÅDE | J5: Grund | K5: =COUNTIFS(L:L,J5) -> 0
A6: Note: | J6: Andet | K6: =COUNTIFS(L:L,J6) -> 0
K7: =SUM(K3:K6) -> 28
M8: Timer pr. uge | P8: Kr/år
A9: DL | B9: Kunde | C9: Selskab | D9: Ejendoms nr | E9: Gruppe | F9: Ejendom | G9: Adresse | H9: Post nr | I9: By | J9: Viceværter | K9: Ny vicevært | L9: Kategori | M9: Vicevært | N9: Gartner | O9: Feje/suge | P9: CTS | Q9: SC | R9: Opstartsdato | S9: Slutdato | T9: FS-aftale | U9: Kommentar | V9: Antal: | W9: PT. DL
A10: RSM | B10: PKA | C10: 11 | D10: 103 | E10: 1 | G10: Linde Allé 28 A + B | H10: 2720 | I10: Vanløse | J10: FS - Helge Madsen/Martin Boy | L10: Boliger | M10: =(100+40+18)/52 -> 3.0384615 | N10: =15/52 -> 0.28846154 | O10: 0 | P10: 0 | Q10: =7650 -> 7650 | R10: 41518 | T10: JA | V10: 1
A11: RSM | B11: PKA | C11: 11 | D11: 104 | E11: 1 | G11: Stilledal 21-33 | H11: 2720 | I11: Vanløse | J11: FS - Helge Madsen/Martin Boy | L11: Boliger | M11: =(125+350+21)/52 -> 9.5384615 | N11: =136/52 -> 2.6153846 | O11: 0 | P11: =2961.4 -> 2961.4 | Q11: =4250 -> 4250 | R11: 41518 | T11: JA | V11: 1
A12: RSM | B12: PKA | C12: 11 | D12: 114 | E12: 1 | G12: Voldumvej 71 - 79 | H12: 2610 | I12: Rødovre | J12: FS - Helge Madsen/Martin Boy | L12: Boliger | M12: =0.971153846153846+5.05769230769231+0.0576923076923077 -> 6.0865385 | N12: 2.25 | O12: 0.038461538 | P12: 0 | Q12: =22400 -> 22400 | R12: 43009 | T12: JA | V12: 1
A13: RSM | B13: PKA | C13: 11 | D13: 350 | E13: 1 | F13: Svanehusene - Irmabyen, Byggefelt 8 | G13: Kaffevej 6-10 og 15-21 | H13: 2610 | I13: Rødovre | J13: FS - Martin Boy | L13: Boliger | M13: 37 | N13: 0 | O13: 0 | P13: 0 | Q13: =30275 -> 30275 | R13: 43344 | S13: 43708 | T13: JA | U13: Antal VV timer ændres. 37 t/uge 1. år, 32 t/uge 2. år, 27,5 t/uge 3. år | V13: 1
A14: RSM | B14: PKA | C14: 11 | D14: 350 | E14: 1 | L14: Boliger | M14: 32 | N14: 0 | O14: 0 | P14: 0 | Q14: =30275 -> 30275 | R14: 43709 | S14: 44074 | T14: JA | U14: 2. drfitsår
A15: RSM | B15: PKA | C15: 11 | D15: 350 | E15: 1 | L15: Boliger | M15: 27.5 | N15: 0 | O15: 0 | P15: 0 | Q15: =30275 -> 30275 | R15: 44075 | T15: JA | U15: 3. driftsår og fremad
A16: RSM | B16: PKA | C16: 11 | D16: 448 | E16: 1 | G16: Rødovrevej 124 A - 132/Voldumvej 9 - 17 | H16: 2610 | I16: Rødovre | J16: FS - Helge Madsen/Martin Boy | L16: Boliger | M16: =1.5+6.7+0.1 -> 8.3 | N16: 4.4 | O16: =10/52 -> 0.19230769 | P16: 0 | Q16: =32900 -> 32900 | R16: 43009 | T16: JA | V16: 1
A17: RSM | B17: PKA | C17: 11 | D17: 449 | E17: 1 | G17: Ålekistevej 81-87 | H17: 2720 | I17: Vanløse | J17: FS - Helge Madsen/Martin Boy | L17: Boliger | M17: =(150+150+14)/52 -> 6.0384615 | N17: =61/52 -> 1.1730769 | O17: 0 | P17: 0 | Q17: 14450 | R17: 41518 | T17: JA | V17: 1
A18: RSM | B18: PKA | C18: 11 | D18: 450 | E18: 1 | G18: Hyltebjerg Allé 32 A - 34 B | H18: 2720 | I18: Vanløse | J18: FS - Helge Madsen/Martin Boy | L18: Boliger | M18: =(100+150+35)/52 -> 5.4807692 | N18: =76/52 -> 1.4615385 | O18: 0 | P18: 0 | Q18: 18700 | R18: 41518 | T18: JA | V18: 1
A19: RSM | B19: By & Havn | C19: 183 | D19: 100 | E19: 1 | F19: Riffelsyndikatet | G19: Southamptongade 4, 1. sal | H19: 2150 | I19: Nordhavn | J19: FS - Tonny L. Hansen/Henrik Kann Jessen | L19: Erhverv | T19: NEJ | U19: Tilsyneladende ingen FS aftale - Aftalen ligger på 8-249 - E/F Riffelsyndikatet | V19: 1
A20: RSM | B20: PKA | C20: 11 | D20: 101 | E20: 1 | F20: Asgården | G20: Valkyriegade 2 - 36/Brynhildegade 12/Haraldsgade 11 | H20: 2200 | I20: København N | J20: FS - Tom P - Michael A - Jan D | L20: Boliger | M20: =(525+700+42)/52 -> 24.365385 | N20: 0.86538462 | O20: 0 | P20: 0 | Q20: =55760 -> 55760 | T20: JA | V20: 1
A21: RSM | B21: PKA | C21: 11 | D21: 115 | E21: 1 | G21: Bjelkes Allé 23 - 35 | H21: 2200 | I21: København N | J21: FS - Tom P - Michael A - Jan D | L21: Boliger | M21: =(300+200+35)/52 -> 10.288462 | N21: =100/52 -> 1.9230769 | O21: 0 | P21: 0 | Q21: =27540 -> 27540 | T21: JA | V21: 1
A22: RSM | B22: PKA | C22: 11 | D22: 141 | E22: 1 | F22: Sygeplejerskernes Hus | G22: Sjællandsgade 59 A-C/Fensmarkgade 1-3/Sjællandsgade 61 A-C/Sjællandsgade 63-69 | H22: 2200 | I22: København N | J22: FS - Tom P - Michael A - Jan D | L22: Boliger | M22: =(500+633+35)/52 -> 22.461538 | N22: =192/52 -> 3.6923077 | O22: 0 | P22: 0 | Q22: =45220 -> 45220 | T22: JA | V22: 1
A23: RSM | B23: PKA | C23: 11 | D23: 165 | E23: 1 | G23: Frederikssundsvej 9/Svanevej 1-3 | H23: 2400 | I23: København NV | J23: FS - Tom P - Michael A - Jan D | L23: Boliger | M23: =(50+175+7)/52 -> 4.4615385 | N23: 0 | O23: 0 | P23: 0 | Q23: =5780 -> 5780 | T23: JA | V23: 1
A24: RSM | B24: PKA | C24: 11 | D24: 367 | E24: 1 | G24: Bomhusvej 6-14 | H24: 2100 | I24: København Ø | J24: FS - Tom P - Michael A - Jan D | L24: Boliger | M24: =(250+100+35+100+12)/52 -> 9.5576923 | N24: =200/52 -> 3.8461538 | O24: 0 | P24: 0 | Q24: =13260 -> 13260 | T24: JA | V24: 1
A25: RSM | B25: PKA | C25: 11 | D25: 430 | E25: 1 | G25: Hørsholmsgade 4-8 | H25: 2200 | I25: København N | J25: FS - Tom P - Michael A - Jan D | L25: Boliger | M25: =(70+70)/52 -> 2.6923077 | N25: 0 | O25: 0 | P25: 0 | Q25: =8160 -> 8160 | T25: JA | V25: 1
A26: RSM | B26: PKA | C26: 11 | D26: 786 | E26: 1 | F26: Lynggården | G26: Rovsingsgade 17-29/Borthigsgade 16-22 | H26: 2101 | I26: København Ø | J26: FS - Tom P - Michael A - Jan D | L26: Boliger | M26: =(312+425+53)/52 -> 15.192308 | N26: =117/52 -> 2.25 | O26: 0 | P26: 0 | Q26: =37400 -> 37400 | T26: JA | V26: 1
A27: RSM | B27: Ejerforening | C27: 8 | D27: 249 | E27: 1 | F27: E/F Riffelsyndikatet | G27: Southhamptongade 2 | H27: 2150 | I27: Nordhavn | J27: FS - Tonny L. Hansen/Henrik Kann Jessen | L27: Boliger | M27: =5.53846153846154+4.48076923076923 -> 10.019231 | N27: 0 | O27: 0 | P27: =(30000+21600) -> 51600 | Q27: 0 | R27: 43497 | T27: JA | V27: 1
A28: RSM | B28: Ejerforening | C28: 8 | D28: 613 | E28: 1 | F28: E/F Sandkaj no. 1 | G28: Trelleborggade 2-6 | H28: 2150 | I28: Nordhavn | J28: FS - Tonny L. Hansen/Henrik Kann Jessen | L28: Boliger | M28: =0.9+1.7+0.2 -> 2.8 | N28: 0 | O28: 0 | P28: 0 | Q28: =8750 -> 8750 | R28: 43466 | T28: JA | V28: 1
A29: RSM | B29: PKA | C29: 11 | D29: 133 | E29: 1 | F29: Øster fællesgård | G29: Vordingborggade 6 A - K | H29: 2100 | I29: København Ø | J29: FS - Tonny L. Hansen/Henrik Kann Jessen | L29: Boliger | M29: =(1031+2356+70+36)/52 -> 67.173077 | N29: =82/52 -> 1.5769231 | O29: 0 | P29: 0 | Q29: =32300 -> 32300 | T29: JA | V29: 1
A30: RSM | B30: PKA | C30: 11 | D30: 308 | E30: 1 | F30: Sandkaj 21 | G30: Sandkaj 21, Antwerpengade 2-4, Bordeauxgade 1-3, Antwerpengade 2-4 Ystadgade 2 og 6 | H30: 2150 | I30: Nordhavn | J30: FS - Tonny L. Hansen/Henrik Kann Jessen | L30: Boliger | M30: =13.4+11+0.3 -> 24.7 | N30: 1 | O30: 0 | P30: =21600 -> 21600 | Q30: =35350 -> 35350 | R30: 42917 | T30: JA | V30: 1
A31: RSM | B31: PKA | C31: 11 | D31: 507 | E31: 1 | G31: Østerbrogade 68 | H31: 2100 | I31: København Ø | J31: FS - Tonny L. Hansen/Henrik Kann Jessen | L31: Boliger | M31: =(36+62+11)/52 -> 2.0961538 | N31: 0 | O31: 0 | P31: 0 | Q31: =2125 -> 2125 | T31: JA | V31: 1
A32: RSM | B32: PKA | C32: 11 | D32: 773 | E32: 1 | G32: Østerbrogade 74-76 Nordre Frihavnsgade 2-4 Odensegade 3 | H32: 2100 | I32: København Ø | J32: FS - Tonny L. Hansen/Henrik Kann Jessen | L32: Boliger | M32: =(61+125+18)/52 -> 3.9230769 | N32: 0 | O32: 0 | P32: 0 | Q32: =5950 -> 5950 | T32: JA | V32: 1
A33: RSM | B33: PensionDanmark | C33: 87 | D33: 507 | E33: 1 | F33: Gardehusarvej 5 m.fl. | G33: Gardehusarvej 5, Garnisonsvej 2-4, Kasernevej 20 | H33: 4700 | I33: Næstved | J33: Ekstern | L33: Erhverv | M33: =1.2+1.8+0.3 -> 3.3 | N33: 2.3 | O33: 0 | P33: 0 | Q33: =9450 -> 9450 | R33: 43983 | T33: JA | V33: 1
A34: RSM | B34: Ejerforening | C34: 8 | D34: 661 | E34: 1 | F34: E/F Sofievej/Strandvejen | G34: Strandvejen 169-171/Sofievej 2-4 | H34: 2900 | I34: Hellerup | J34: Jan Drejer | L34: Boliger | M34: =2+5.2+0.6 -> 7.8 | N34: 2.2 | O34: =(14+24)/52 -> 0.73076923 | P34: 0 | Q34: =11600 -> 11600 | R34: 43709 | T34: JA | V34: 1
A35: RSM | C35: 11 | D35: 155 | G35: Strandvejen 169-171 | H35: 2900 | I35: Hellerup | J35: Jan Drejer | L35: Erhverv | M35: =(13+150+11)/52 -> 3.3461538 | N35: 0 | O35: 0 | P35: 0 | Q35: 4250 | T35: JA | V35: 1
A36: RSM | C36: 11 | D36: 159 | G36: Bryggertorvet 2-6, Strandvejen 62-68 m.fl. | H36: 2900 | I36: Hellerup | J36: Jan Drejer, Tom Petersen, Michael Andersen | L36: Boliger | M36: =93/52 -> 1.7884615 | N36: 0 | O36: 0 | P36: 0 | Q36: =6317.5 -> 6317.5 | R36: 42036 | T36: JA | V36: 1
A37: RSM | C37: 11 | D37: 395 | F37: Solgården | G37: Rebekkavej 59 m.fl. | H37: 2900 | I37: Hellerup | J37: Jan Drejer, Tom Petersen, Michael Andersen | L37: Boliger | M37: =(7+4)/52 -> 0.21153846 | N37: 0 | O37: 0 | P37: 0 | Q37: 850 | T37: JA | V37: 1

Sheet 2-Thomas
A1: Thomas Olsen - 20
A2: GRUPPE 2 -
A3: Antal ejendomme | C3: =K7 -> 45 | J3: Erhverv | K3: =COUNTIFS(L:L,J3) -> 12
A4: Viceværter: | J4: Boliger | K4: =COUNTIFS(L:L,J4) -> 29
A5: Note: | J5: Grund | K5: =COUNTIFS(L:L,J5) -> 0
J6: Andet | K6: =COUNTIFS(L:L,J6) -> 4
K7: =SUM(K3:K6) -> 45
M8: Timer pr. uge | P8: Kr/år
A9: DL | B9: Kunde | C9: Selskab | D9: Ejendoms nr | E9: Gruppe | F9: Ejendom | G9: Adresse | H9: Post nr | I9: By | J9: Viceværter | K9: Ny vicevært | L9: Kategori | M9: Vicevært | N9: Gartner | O9: Feje/suge | P9: CTS | Q9: SC | R9: Opstartsdato | S9: Slutdato | T9: FS-aftale | U9: Kommentar | V9: Antal: | W9: PT. DL
A10: THOL | B10: Ejerforening | C10: 8 | D10: 150 | E10: 2 | F10: E/F Tøjhus Have | G10: Myggenæsgade 3-11 | H10: 2300 | I10: København S | J10: Michael Thaysen | L10: Boliger | T10: NEJ | U10: Ligger under "tabte" sager i tilbud | V10: 1
A11: THOL | B11: Ejerforening | C11: 8 | D11: 291 | E11: 2 | F11: E/F Kronborg Strand I | G11: Strandpromenaden 37-49 | H11: 3000 | I11: Helsingør | J11: FS - Jan Hemmersam | L11: Boliger | M11: =0.980769230769231+0.269230769230769 -> 1.25 | N11: 0 | O11: 0 | P11: 0 | Q11: =7350 -> 7350 | R11: 43770 | T11: JA | V11: 1
A12: THOL | B12: Ejerforening | C12: 8 | D12: 293 | E12: 2 | F12: G/F Kronborg Strand | G12: Strandpromenaden 17-67 | H12: 3000 | I12: Helsingør | J12: FS - Jan Hemmersam | L12: Andet | M12: 5.4230769 | N12: 0 | O12: 0 | P12: 0 | Q12: =9100 -> 9100 | R12: 43770 | T12: JA | V12: 1
A13: THOL | B13: Ejerforening | C13: 8 | D13: 351 | E13: 2 | F13: E/F Holbæk fjordtårn | G13: Isefjords Allé 13-15 | H13: 4300 | I13: Holbæk | J13: FS - Jan Hemmersam | L13: Boliger | M13: =1.68307692307692+4.20192307692308 -> 5.885 | N13: 0 | O13: 0 | P13: 0 | Q13: =15050 -> 15050 | R13: 43794 | T13: JA | V13: 1
A14: THOL | B14: Ejerforening | C14: 8 | D14: 359 | E14: 2 | F14: E/F Flintholm Have | G14: Preben Kaas Vænge 2-8, Flintholm Allé 20, Dirch Passers Allé 17-27 Flintholm Allé 20-26 | H14: 2000 | I14: Frederiksberg | J14: FS - Simon Lyster | L14: Boliger | M14: =1.44230769230769+6.57692307692308 -> 8.0192308 | N14: 3.8365385 | O14: 0 | P14: 0 | Q14: =15050 -> 15050 | R14: 43040 | T14: JA | V14: 1
A15: THOL | B15: Ejerforening | C15: 8 | D15: 404 | E15: 2 | F15: E/F Vodroffsvej 2 A-B | G15: Vodroffsvej 2 A-B | H15: 1900 | I15: Frederiksberg C | J15: Glad Ejendomsservice | L15: Boliger | T15: NEJ | U15: Ligger under "tabte" sager i tilbud | V15: 1
A16: THOL | B16: Ejerforening | C16: 8 | D16: 603 | E16: 2 | F16: E/F Revyhaven | G16: Dirch Passers Allé 3-15, Elga Olgas Vej 1-3 | H16: 2000 | I16: Frederiksberg | J16: FS - Simon Lyster | L16: Boliger | M16: =436.25/52 -> 8.3894231 | N16: =205.5/52 -> 3.9519231 | O16: =8/52 -> 0.15384615 | P16: 0 | Q16: =13095 -> 13095 | R16: 41988 | T16: NEJ | V16: 1
A17: THOL | B17: Balsløw | C17: 9 | D17: 140 | E17: 2 | F17: Bondebyerne Hellerup Havnepalæ A/S | G17: Jomsborgvej 37-41 | H17: 2900 | I17: Hellerup | J17: - | L17: Andet | T17: NEJ | U17: Ligger under en ejendomsoversigt, men ingen kalkulationer | V17: 1
A18: THOL | B18: Balsløw | C18: 9 | D18: 141 | E18: 2 | F18: Bondebyerne | G18: Asylgade 8 | H18: 2800 | I18: Kgs. Lyngby | J18: Lars Nielsen | L18: Boliger | T18: NEJ | U18: Ligger under en ejendomsoversigt, men ingen kalkulationer | V18: 1
A19: THOL | B19: Balsløw | C19: 9 | D19: 142 | E19: 2 | F19: Bondebyerne | G19: Toftegærdet 25 A-B | H19: 2800 | I19: Kgs. Lyngby | J19: Lars Nielsen | L19: Boliger | T19: NEJ | U19: Ligger under en ejendomsoversigt, men ingen kalkulationer | V19: 1
A20: THOL | B20: Balsløw | C20: 9 | D20: 143 | E20: 2 | F20: Bondebyerne | G20: Peter Lunds Vej 10-12 A-B | H20: 2800 | I20: Kgs. Lyngby | J20: Lars Nielsen | L20: Boliger | T20: NEJ | U20: Ligger under en ejendomsoversigt, men ingen kalkulationer | V20: 1
A21: THOL | B21: Balsløw | C21: 9 | D21: 144 | E21: 2 | F21: Bondebyerne | G21: Asylgade 4/Nørregade 3A | H21: 2800 | I21: Kgs. Lyngby | J21: Lars Nielsen | L21: Boliger | M21: =(10+6.5+2.5)/52 -> 0.36538462 | N21: 0 | O21: 0 | P21: 0 | Q21: 0 | R21: 43891 | T21: NEJ | V21: 1
A22: THOL | B22: Balsløw | C22: 9 | D22: 145 | E22: 2 | F22: Bondebyerne | G22: Asylgade 6 | H22: 2800 | I22: Kgs. Lyngby | J22: Lars Nielsen | L22: Boliger | M22: 0.36538462 | N22: 0 | O22: 0 | P22: 0 | Q22: 0 | R22: 43891 | T22: NEJ | V22: 1
A23: THOL | B23: Balsløw | C23: 9 | D23: 146 | E23: 2 | F23: HHP Ejendomme 2 ApS, bondebyerne | G23: Jomsborgvej 41 st. | H23: 2900 | I23: Hellerup | J23: - | L23: Andet | T23: NEJ | U23: Ligger under en ejendomsoversigt, men ingen kalkulationer | V23: 1
A24: THOL | B24: Balsløw | C24: 9 | D24: 553 | E24: 2 | F24: Hellerup Havnepalæ A/S | G24: Jomsborgvej 37-41 | H24: 2900 | I24: Hellerup | J24: Exact Ejendomsservice | L24: Boliger | M24: 0.85576923 | N24: 0 | O24: 0 | P24: 0 | Q24: 0 | R24: 43891 | T24: NEJ | V24: 1
A25: THOL | B25: Balsløw | C25: 9 | D25: 555 | E25: 2 | F25: J.C.B.Hellerup Leasing ApS | G25: Hellerupvej 8 | H25: 2900 | I25: Hellerup | J25: - | L25: Erhverv | T25: NEJ | U25: Ligger under en ejendomsoversigt, men ingen kalkulationer | V25: 1
A26: THOL | B26: Balsløw | C26: 9 | D26: 556 | E26: 2 | F26: Hellerupvej 8, Jens Balsløw | G26: Hellerupvej 8 | H26: 2900 | I26: Hellerup | J26: - | L26: Erhverv | T26: NEJ | U26: Ligger under en ejendomsoversigt, men ingen kalkulationer | V26: 1
A27: THOL | B27: Balsløw | C27: 9 | D27: 559 | E27: 2 | F27: HHP Ejendomme ApS | G27: Viktoriagade 16 og 16 C | H27: 1655 | I27: København V | J27: Exact Ejendomsservice | L27: Boliger | M27: 0.52884615 | N27: 0 | O27: 0 | P27: 0 | Q27: 0 | R27: 43891 | T27: NEJ | V27: 1
A28: THOL | B28: AP Pension | C28: 13 | D28: 404 | E28: 2 | G28: Vodroffsvej 2 A-B | H28: 1900 | I28: Frederiksberg C | J28: - | L28: Boliger | M28: 0 | N28: 0 | O28: 0 | P28: 0 | Q28: =3850 -> 3850 | R28: 42552 | T28: JA | U28: Tvivl om opstartsdato | V28: 1
A29: THOL | B29: AP Pension | C29: 13 | D29: 410 | E29: 2 | G29: Vallensbækvej 51-53 | H29: 2605 | I29: Brøndby | J29: - | L29: Boliger | T29: NEJ | U29: Tilsyneladende ingen FS-aftale | V29: 1
A30: THOL | B30: AP Pension | C30: 13 | D30: 516 | E30: 2 | F30: Lindegårdsvej | G30: Lindegårdsvej 38 A | H30: 2920 | I30: Charlottenlund | J30: Ejendomsservice Kurt Svendsen | L30: Boliger | T30: NEJ | U30: Tilsyneladende ingen FS-aftale | V30: 1
A31: THOL | B31: AP Pension | C31: 13 | D31: 520 | E31: 2 | G31: Østbanegade 135/Århusgade 112 | H31: 2100 | I31: København Ø | J31: Henning L. Culmsee | L31: Erhverv | T31: NEJ | U31: Tilsyneladende ingen FS-aftale | V31: 1
A32: THOL | B32: AP Pension | C32: 13 | D32: 522 | E32: 2 | G32: Priorparken 470 | H32: 2605 | I32: Brøndby | J32: - | L32: Erhverv | T32: NEJ | U32: Tilsyneladende ingen FS-aftale | V32: 1
A33: THOL | B33: AP Pension | C33: 13 | D33: 523 | E33: 2 | F33: Montebello | G33: Gurrevej 90/Gurrevej 90 A - C | H33: 3000 | I33: Helsingør | J33: Kim Pedersen | L33: Erhverv | T33: NEJ | U33: Tilsyneladende ingen FS-aftale | V33: 1
A34: THOL | B34: AP Pension | C34: 13 | D34: 524 | E34: 2 | F34: Fejøgade | G34: Fejøgade 1/Strandgade 24 | H34: 4800 | I34: Nykøbing F | J34: Rask El Service | L34: Erhverv | T34: NEJ | U34: Tilsyneladende ingen FS-aftale | V34: 1
A35: THOL | B35: AP Pension | C35: 13 | D35: 525 | E35: 2 | G35: Sydvestvej 15-23 | H35: 2600 | I35: Glostrup | J35: Tjek Bygningsservice | L35: Erhverv | T35: NEJ | U35: Tilsyneladende ingen FS-aftale | V35: 1
A36: THOL | B36: AP Pension | C36: 13 | D36: 535 | E36: 2 | G36: Strødamvej 52 | H36: 2100 | I36: København Ø | J36: - | L36: Erhverv | T36: NEJ | U36: Tilsyneladende ingen FS-aftale | V36: 1
A37: THOL | B37: AP Pension | C37: 13 | D37: 536 | E37: 2 | G37: Greve Main 21 | H37: 2670 | I37: Greve | J37: - | L37: Erhverv | T37: NEJ | U37: Tilsyneladende ingen FS-aftale | V37: 1
A38: THOL | B38: AP Pension | C38: 13 | D38: 540 | E38: 2 | G38: Buddingevej 193 - 195 | H38: 2860 | I38: Søborg | J38: Uno X Brian Petersen | L38: Erhverv | T38: NEJ | U38: Tilsyneladende ingen FS-aftale | V38: 1
A39: THOL | B39: AP Pension | C39: 13 | D39: 552 | E39: 2 | G39: Borgmester Christiansens Gade 55 | H39: 2450 | I39: København SV | J39: - | L39: Erhverv | T39: NEJ | U39: Tilsyneladende ingen FS-aftale | V39: 1
A40: THOL | B40: AP Pension | C40: 13 | D40: 560 | E40: 2 | F40: Tårnby Torv | G40: Tårnby Torv 3 | H40: 2770 | I40: Kastrup | J40: Rygges Multiservice | L40: Erhverv | T40: NEJ | U40: Tilsyneladende ingen FS-aftale | V40: 1
...

Sheet 2-Martin
A1: Martin Kjærsgaard - 6
A2: GRUPPE 2 -
A3: Antal ejendomme | C3: =K7 -> 37 | J3: Erhverv | K3: =COUNTIFS(L:L,J3) -> 0
A4: Viceværter: | J4: Boliger | K4: =COUNTIFS(L:L,J4) -> 35
A5: Note: | J5: Grund | K5: =COUNTIFS(L:L,J5) -> 0
J6: Andet | K6: =COUNTIFS(L:L,J6) -> 2
K7: =SUM(K3:K6) -> 37
M8: Timer pr. uge | P8: Kr/år
A9: DL | B9: Kunde | C9: Selskab | D9: Ejendoms nr | E9: Gruppe | F9: Ejendom | G9: Adresse | H9: Post nr | I9: By | J9: Viceværter | K9: Ny vicevært | L9: Kategori | M9: Vicevært | N9: Gartner | O9: Feje/suge | P9: CTS | Q9: SC | R9: Opstartsdato | S9: Slutdato | T9: FS-aftale | U9: Kommentar | V9: Antal: | W9: PT. DL
A10: MKJ | B10: Sampension | C10: 20 | D10: 214 | E10: 2 | F10: Hoffmeyersvej 59-69 m.fl. | G10: Hoffmeyersvej 59-69/Roskildevej 72-74/Hoffmeyersvej 59-69 | H10: 2000 | I10: Frederiksberg | J10: FS - Johnny Faigh | L10: Boliger | S10: 30.09.2020 | T10: JA | U10: Kun oversigtskort, ingen FS-aftale eller tilhørende kalkulationer | V10: 1
A11: MKJ | B11: Kraemers legat | C11: 39 | D11: 851 | E11: 2 | G11: Blegdamsvej 126, 126 A, 126 B | H11: 2100 | I11: København Ø | J11: Claus Fonnest | L11: Boliger | T11: NEJ | U11: Ingen FS | V11: 1
A12: MKJ | B12: Kraemers legat | C12: 39 | D12: 852 | E12: 2 | G12: H. C. Ørsteds Vej 66 - 68 | H12: 1879 | I12: Frederiksberg C | J12: Servicefrabrikken Stefan Pokomi | L12: Boliger | T12: NEJ | U12: Ingen FS | V12: 1
A13: MKJ | B13: Kraemers legat | C13: 39 | D13: 853 | E13: 2 | F13: Lyongade 16-20 m.fl. | G13: Lyongade 16-20/Spaniensgade 22/Saltholmvej 1 | H13: 2300 | I13: København S | J13: Claus Fonnest | L13: Boliger | T13: NEJ | U13: Ingen FS | V13: 1
A14: MKJ | B14: Kraemers legat | C14: 39 | D14: 854 | E14: 2 | F14: Nørrebrogade 74 - 76 m.fl. | G14: Meinungsgade 4/Nørrebrogade 74 - 76, 74A | H14: 2200 | I14: København N | J14: Claus Fonnest | L14: Boliger | T14: NEJ | U14: Ingen FS | V14: 1
A15: MKJ | B15: Kraemers legat | C15: 39 | D15: 855 | E15: 2 | G15: Øresundsvej 38 - 44 | H15: 2300 | I15: København S | J15: Claus Fonnest | L15: Boliger | T15: NEJ | U15: Ingen FS | V15: 1
A16: MKJ | B16: Thylander | C16: 41 | D16: 891 | E16: 2 | F16: Haraldsborg | G16: Islands Brygge 15-19/Reykjavikgade 2-4/Thorshavnsgade 26-28/Njalsgade 1 | H16: 2300 | I16: København S | J16: KEH-gruppen | L16: Boliger | M16: 0 | N16: 0 | O16: 0 | P16: 0 | Q16: =(1147.53*12) -> 13770.36 | T16: JA | U16: Kun SC | V16: 1
A17: MKJ | B17: Thylander | C17: 41 | D17: 893 | E17: 2 | G17: C. F. Richs vej 99 - 101 | H17: 2000 | I17: Frederiksberg | J17: KEH-gruppen | L17: Boliger | M17: 0 | N17: 0 | O17: 0 | P17: 0 | Q17: =(1642.78*12) -> 19713.36 | T17: JA | U17: Kun SC | V17: 1
A18: MKJ | B18: Thylander | C18: 41 | D18: 894 | E18: 2 | F18: Munken | G18: Nitivej 9-15/Priorvej 2-8 | H18: 2000 | I18: Frederiksberg | J18: KEH-gruppen | L18: Boliger | M18: 0 | N18: 0 | O18: 0 | P18: 0 | Q18: =(978.42*12) -> 11741.04 | T18: JA | U18: Kun SC | V18: 1
A19: MKJ | B19: Thylander | C19: 41 | D19: 895 | E19: 2 | F19: Søborg Huse | G19: Søborghus Park 1-24/Frederiksborgvej 221 | H19: 2860 | I19: Søborg | J19: KEH-gruppen | L19: Boliger | M19: 0 | N19: 0 | O19: 0 | P19: 0 | Q19: =(2500.41*12) -> 30004.92 | T19: JA | U19: Kun SC | V19: 1
A20: MKJ | B20: Thylander | C20: 41 | D20: 897 | E20: 2 | F20: Høeghsmindeparken | G20: Høeghsmindeparken 2 - 16/Bernstorffsvej 142 - 148 | H20: 2900 | I20: Hellerup | J20: KEH-gruppen | L20: Boliger | M20: 0 | N20: 0 | O20: 0 | P20: 0 | Q20: =(1195.85*12) -> 14350.2 | T20: JA | U20: Kun SC | V20: 1
A21: MKJ | B21: Thylander | C21: 41 | D21: 898 | E21: 2 | F21: Ved Boldparken/Peter Bangs Vej 113 mf. | G21: Peter Bangs Vej 113-145/Peter Bangs Vej 149-163 | H21: 2000 | I21: Frederiksberg | J21: KEH-gruppen | L21: Boliger | M21: 0 | N21: 0 | O21: 0 | P21: 0 | Q21: =(3660.02*12) -> 43920.24 | T21: JA | U21: Kun SC | V21: 1
A22: MKJ | B22: Thylander | C22: 41 | D22: 9999 | E22: 2 | F22: Carlsbergfondet budgetenhed | G22: Dirch Passers Allé 76 | H22: 2000 | I22: Frederiksberg | L22: Andet | M22: 0 | N22: 0 | O22: 0 | P22: 0 | T22: NEJ | V22: 1
A23: MKJ | B23: Tårnfalke Holding A/S | C23: 45 | D23: 987 | E23: 2 | G23: Valby Langgade 70 | H23: 2500 | I23: Valby | J23: Gårdmand Bjørn Aps | L23: Boliger | M23: 0 | N23: 0 | O23: 0 | P23: 0 | T23: NEJ | V23: 1
A24: MKJ | B24: Tårnfalke Holding A/S | C24: 45 | D24: 989 | E24: 2 | G24: Valby Langgade 215 | H24: 2500 | I24: Valby | J24: Gårdmand Bjørn Aps | L24: Boliger | M24: 0 | N24: 0 | O24: 0 | P24: 0 | T24: NEJ | V24: 1
A25: MKJ | B25: Frederiksberg Fonden | C25: 59 | D25: 1 | E25: 2 | F25: Peter Bangs Vej 83 - 89 m.fl. | G25: Peter Bangs Vej 83-89/Glahns Allé 1-5/Hattensens Allé 22-26 | H25: 2000 | I25: Frederiksberg | J25: FS - Johnny Faigh | L25: Boliger | M25: =5.07692289352416+4.567307472229+0.230769231915474 -> 9.8749996 | N25: 4.3076925 | O25: 0 | P25: 0 | Q25: =700 -> 700 | R25: 42948 | T25: JA | V25: 1
